try {
    name=23
    console.log(name);
    
} catch (error) {
    console.log("Error in catch block", error);
}

var name;